Exception on /get_tasks [POST]
Traceback (most recent call last):
  File "/Users/wuoix/Documents/Code/Spitlist/ENV/lib/python2.7/site-packages/flask/app.py", line 1817, in wsgi_app
    response = self.full_dispatch_request()
  File "/Users/wuoix/Documents/Code/Spitlist/ENV/lib/python2.7/site-packages/flask/app.py", line 1477, in full_dispatch_request
    rv = self.handle_user_exception(e)
  File "/Users/wuoix/Documents/Code/Spitlist/ENV/lib/python2.7/site-packages/flask/app.py", line 1381, in handle_user_exception
    reraise(exc_type, exc_value, tb)
  File "/Users/wuoix/Documents/Code/Spitlist/ENV/lib/python2.7/site-packages/flask/app.py", line 1475, in full_dispatch_request
    rv = self.dispatch_request()
  File "/Users/wuoix/Documents/Code/Spitlist/ENV/lib/python2.7/site-packages/flask/app.py", line 1461, in dispatch_request
    return self.view_functions[rule.endpoint](**req.view_args)
  File "/Users/wuoix/Documents/Code/Spitlist/app/views.py", line 19, in get_tasks
    task.task_id = 1
NameError: global name 'task' is not defined
Exception on /get_tasks [POST]
Traceback (most recent call last):
  File "/Users/wuoix/Documents/Code/Spitlist/ENV/lib/python2.7/site-packages/flask/app.py", line 1817, in wsgi_app
    response = self.full_dispatch_request()
  File "/Users/wuoix/Documents/Code/Spitlist/ENV/lib/python2.7/site-packages/flask/app.py", line 1477, in full_dispatch_request
    rv = self.handle_user_exception(e)
  File "/Users/wuoix/Documents/Code/Spitlist/ENV/lib/python2.7/site-packages/flask/app.py", line 1381, in handle_user_exception
    reraise(exc_type, exc_value, tb)
  File "/Users/wuoix/Documents/Code/Spitlist/ENV/lib/python2.7/site-packages/flask/app.py", line 1475, in full_dispatch_request
    rv = self.dispatch_request()
  File "/Users/wuoix/Documents/Code/Spitlist/ENV/lib/python2.7/site-packages/flask/app.py", line 1461, in dispatch_request
    return self.view_functions[rule.endpoint](**req.view_args)
  File "/Users/wuoix/Documents/Code/Spitlist/app/views.py", line 19, in get_tasks
    task = {}
NameError: global name 'task' is not defined
Exception on /get_tasks [POST]
Traceback (most recent call last):
  File "/Users/wuoix/Documents/Code/Spitlist/ENV/lib/python2.7/site-packages/flask/app.py", line 1817, in wsgi_app
    response = self.full_dispatch_request()
  File "/Users/wuoix/Documents/Code/Spitlist/ENV/lib/python2.7/site-packages/flask/app.py", line 1477, in full_dispatch_request
    rv = self.handle_user_exception(e)
  File "/Users/wuoix/Documents/Code/Spitlist/ENV/lib/python2.7/site-packages/flask/app.py", line 1381, in handle_user_exception
    reraise(exc_type, exc_value, tb)
  File "/Users/wuoix/Documents/Code/Spitlist/ENV/lib/python2.7/site-packages/flask/app.py", line 1475, in full_dispatch_request
    rv = self.dispatch_request()
  File "/Users/wuoix/Documents/Code/Spitlist/ENV/lib/python2.7/site-packages/flask/app.py", line 1461, in dispatch_request
    return self.view_functions[rule.endpoint](**req.view_args)
  File "/Users/wuoix/Documents/Code/Spitlist/app/views.py", line 20, in get_tasks
    task.task_id = 1
AttributeError: 'dict' object has no attribute 'task_id'
Exception on /get_tasks [POST]
Traceback (most recent call last):
  File "/Users/wuoix/Documents/Code/Spitlist/ENV/lib/python2.7/site-packages/flask/app.py", line 1817, in wsgi_app
    response = self.full_dispatch_request()
  File "/Users/wuoix/Documents/Code/Spitlist/ENV/lib/python2.7/site-packages/flask/app.py", line 1477, in full_dispatch_request
    rv = self.handle_user_exception(e)
  File "/Users/wuoix/Documents/Code/Spitlist/ENV/lib/python2.7/site-packages/flask/app.py", line 1381, in handle_user_exception
    reraise(exc_type, exc_value, tb)
  File "/Users/wuoix/Documents/Code/Spitlist/ENV/lib/python2.7/site-packages/flask/app.py", line 1475, in full_dispatch_request
    rv = self.dispatch_request()
  File "/Users/wuoix/Documents/Code/Spitlist/ENV/lib/python2.7/site-packages/flask/app.py", line 1461, in dispatch_request
    return self.view_functions[rule.endpoint](**req.view_args)
  File "/Users/wuoix/Documents/Code/Spitlist/app/views.py", line 28, in get_tasks
    tasks = tasks)
  File "/Users/wuoix/Documents/Code/Spitlist/ENV/lib/python2.7/site-packages/flask/templating.py", line 127, in render_template
    return _render(ctx.app.jinja_env.get_or_select_template(template_name_or_list),
  File "/Users/wuoix/Documents/Code/Spitlist/ENV/lib/python2.7/site-packages/jinja2/environment.py", line 830, in get_or_select_template
    return self.get_template(template_name_or_list, parent, globals)
  File "/Users/wuoix/Documents/Code/Spitlist/ENV/lib/python2.7/site-packages/jinja2/environment.py", line 791, in get_template
    return self._load_template(name, self.make_globals(globals))
  File "/Users/wuoix/Documents/Code/Spitlist/ENV/lib/python2.7/site-packages/jinja2/environment.py", line 765, in _load_template
    template = self.loader.load(self, name, globals)
  File "/Users/wuoix/Documents/Code/Spitlist/ENV/lib/python2.7/site-packages/jinja2/loaders.py", line 125, in load
    code = environment.compile(source, name, filename)
  File "/Users/wuoix/Documents/Code/Spitlist/ENV/lib/python2.7/site-packages/jinja2/environment.py", line 554, in compile
    self.handle_exception(exc_info, source_hint=source)
  File "/Users/wuoix/Documents/Code/Spitlist/ENV/lib/python2.7/site-packages/jinja2/environment.py", line 742, in handle_exception
    reraise(exc_type, exc_value, tb)
  File "/Users/wuoix/Documents/Code/Spitlist/app/templates/tasks.html", line 2, in template
    {% for each task in tasks %}
TemplateSyntaxError: expected token 'in', got 'task'
